<?xml version="1.0"?>
<robot name="test_robot">

  <link name="base_link">
    <visual>
      <geometry>
        <box size="0.5 0.5 0.1"/>
      </geometry>
      <origin rpy="0 0 0" xyz="0 0 0.2"/>
      <material name="white">
        <color rgba="1 1 1 1"/>
      </material>
    </visual>
    <inertial>
      <origin xyz="0.0 0.0 0.2" rpy="0.0 0.0 0.0"/>
      <mass value="40.0"/>
      <inertia ixx="0.8666666666666667" ixy="0.0" ixz="0.0" iyy="0.8666666666666667" iyz="0.0" izz="1.6666666666666667"/>
    </inertial>
    <collision>
      <geometry>
        <box size="0.5 0.5 0.1"/>
      </geometry>
      <origin rpy="0 0 0" xyz="0 0 0.2"/>
    </collision>

  </link>
  
  <!-- upper -->
  <link name="extention">
    <visual>
      <geometry>
        <box size="0.1 0.1 0.375"/>
      </geometry>
      <origin rpy="0 0 0" xyz="0 0 0"/>
      <material name="white">
        <color rgba="0 0 0 1"/>
      </material>
    </visual>
    <inertial>
      <origin xyz="0.0 0.0 0.0" rpy="0.0 0.0 0.0"/>
      <mass value="10.0"/>
      <inertia ixx="0.12552083333333336" ixy="0.0" ixz="0.0" iyy="0.12552083333333336" iyz="0.0" izz="0.01666666666666667"/>
    </inertial>
    <collision>
      <geometry>
        <box size="0.1 0.1 0.375"/>
      </geometry>
      <origin rpy="0 0 0" xyz="0 0 0"/>
    </collision>
  </link>
<!-- upper   -->

<!-- lower   -->
  <joint name="base_to_extention" type="fixed">
    <parent link="base_link"/>
    <child link="extention"/>
    <origin xyz="0.0 0.0 0.4375" rpy="0 0 0"/>
    <axis xyz="0.0 0.0 0.0"/>
  </joint>
<!-- lower   -->

<!-- after base link if size change at upper ,if origin axiz change at lower -->

<!-- upper -->
  <link name="lwheel">
    <visual>
      <geometry>
        <cylinder length="0.05" radius="0.2"/>
      </geometry>
      <origin rpy="0 0 0" xyz="0 0 0"/>
      <material name="white">
        <color rgba="0 0 0 1"/>
      </material>
    </visual>
    <inertial>
      <origin xyz="0.0 0.0 0.0" rpy="0.0 0.0 0.0"/>
      <mass value="1.0"/>
      <inertia ixx="0.010208333333333335" ixy="0.0" ixz="0.0" iyy="0.010208333333333335" iyz="0.0" izz="0.020000000000000004"/>
    </inertial>
    <collision>
      <geometry>
        <cylinder length="0.05" radius="0.2"/>
      </geometry>
      <origin rpy="0 0 0" xyz="0 0 0"/>
    </collision>
  </link>
<!-- upper   -->

<!-- lower   -->
  <joint name="base_to_lwheel" type="continuous">
    <parent link="base_link"/>
    <child link="lwheel"/>
    <origin xyz="-0.0 0.275 0.2" rpy="1.5708 0 0"/>
    <axis xyz="0.0 0.0 -1.0"/>
    <limit effort="100.0" velocity="100.0"/>
    <joint_properties damping="0.0" friction="0.0"/>
  </joint>
<!-- lower   -->

  <link name="rwheel">
    <visual>
      <geometry>
        <cylinder length="0.05" radius="0.2"/>
      </geometry>
      <origin rpy="0 0 0" xyz="0 0 0"/>
      <material name="white">
        <color rgba="0 0 0 1"/>
      </material>
    </visual>
    <inertial>
      <origin xyz="0.0 0.0 0.0" rpy="0 0 0"/>
      <mass value="1.0"/>
      <inertia ixx="0.010208333333333335" ixy="0.0" ixz="0.0" iyy="0.010208333333333335" iyz="0.0" izz="0.020000000000000004"/>
    </inertial> 
    <collision>
      <geometry>
        <cylinder length="0.05" radius="0.2"/>
      </geometry>
      <origin rpy="0 0 0" xyz="0 0 0"/>
    </collision>  
  </link>
  
  <joint name="base_to_rwheel" type="continuous">
    <parent link="base_link"/>
    <child link="rwheel"/>
    <origin xyz="-0.0 -0.275 0.2" rpy="1.5708 0 0"/>
    <axis xyz="0.0 0.0 -1.0"/>
    <limit effort="100.0" velocity="100.0"/>
    <joint_properties damping="0.0" friction="0.0"/>
  </joint>


  <link name="fwheel">
    <visual>
      <geometry>
        <sphere radius="0.1"/>
      </geometry>
      <origin rpy="0 0 0" xyz="0 0 0"/>
      <material name="white">
        <color rgba="0 0 0 1"/>
      </material>
    </visual>
    <inertial>
      <origin xyz="0.0 0.0 0.0" rpy="0.0 0.0 0.0"/>
      <mass value="0.25"/>
      <inertia ixx="0.0010000000000000002" ixy="0.0" ixz="0.0" iyy="0.0010000000000000002" iyz="0.0" izz="0.0010000000000000002"/>
    </inertial>
    <collision>
      <geometry>
        <sphere radius="0.1"/>
      </geometry>
      <origin rpy="0 0 0" xyz="0 0 0"/>
    </collision>
  </link>
  
  <joint name="base_to_fwheel" type="continuous">
    <parent link="base_link"/>
    <child link="fwheel"/>
    <origin xyz="0.25 0 0.1" rpy="0 0 0"/>
    <axis xyz="1.0 1.0 1.0"/>
    <limit effort="100.0" velocity="100.0"/>
    <joint_properties damping="0.0" friction="0.0"/>
  </joint>


  <link name="bwheel">
    <visual>
      <geometry>
        <sphere radius="0.1"/>
      </geometry>
      <origin rpy="0 0 0" xyz="0 0 0"/>
      <material name="white">
        <color rgba="0 0 0 1"/>
      </material>
    </visual>
    <inertial>
      <origin xyz="0.0 0.0 0.0" rpy="0.0 0.0 0.0"/>
      <mass value="0.25"/>
      <inertia ixx="0.0010000000000000002" ixy="0.0" ixz="0.0" iyy="0.0010000000000000002" iyz="0.0" izz="0.0010000000000000002"/>
    </inertial>
    <collision>
      <geometry>
        <sphere radius="0.1"/>
      </geometry>
      <origin rpy="0 0 0" xyz="0 0 0"/>
    </collision>
  </link>
  
  <joint name="base_to_bwheel" type="continuous">
    <parent link="base_link"/>
    <child link="bwheel"/>
    <origin xyz="-0.25 0 0.1" rpy="0 0 0"/>
    <axis xyz="1.0 1.0 1.0"/>
    <limit effort="100.0" velocity="100.0"/>
    <joint_properties damping="0.0" friction="0.0"/>
  </joint>

  
  
  
  <transmission name="left_wheel_transmission">
    <type>transmission_interface/SimpleTransmission</type>
    <joint name="base_to_lwheel">
      <hardwareInterface>hardware_interface/VelocityJointInterface</hardwareInterface>  
    </joint>
    <actuator name="left_wheel_actuator">
      <mechanicalReduction>7</mechanicalReduction>
      <hardwareInterface>VelocityJointInterface</hardwareInterface>
    </actuator>
  </transmission>

  <transmission name="right_wheel_transmission">
    <type>transmission_interface/SimpleTransmission</type>
    <joint name="base_to_rwheel">
      <hardwareInterface>hardware_interface/VelocityJointInterface</hardwareInterface>  
    </joint>
    <actuator name="right_wheel_actuator">
      <mechanicalReduction>7</mechanicalReduction>
      <hardwareInterface>VelocityJointInterface</hardwareInterface>
    </actuator>
  </transmission>

  <transmission name="fwheel_transmission">
    <type>transmission_interface/SimpleTransmission</type>
    <joint name="base_to_fwheel">
      <hardwareInterface>hardware_interface/VelocityJointInterface</hardwareInterface>  
    </joint>
    <actuator name="fwheel_actuator">
      <mechanicalReduction>7</mechanicalReduction>
      <hardwareInterface>VelocityJointInterface</hardwareInterface>
    </actuator>
  </transmission>

  <transmission name="bwheel_transmission">
    <type>transmission_interface/SimpleTransmission</type>
    <joint name="base_to_bwheel">
      <hardwareInterface>hardware_interface/VelocityJointInterface</hardwareInterface>  
    </joint>
    <actuator name="bwheel_actuator">
      <mechanicalReduction>7</mechanicalReduction>
      <hardwareInterface>VelocityJointInterface</hardwareInterface>
    </actuator>
  </transmission>

  <gazebo>
    <plugin name="gazebo_ros_control" filename="libgazebo_ros_control.so">
    </plugin>

  </gazebo>

  <!-- Hokuyo Laser -->
  <link name="hokuyo_link">
    <collision>
      <origin xyz="0 0 0" rpy="0 0 0"/>
      <geometry>
    <box size="0.1 0.1 0.1"/>
      </geometry>
    </collision>

    <visual>
      <origin xyz="0 0 0" rpy="0 0 0"/>
      <geometry>
        <mesh filename="package://banks_dd/model/hokuyo.dae"/>
      </geometry>
    </visual>

    <inertial>
      <mass value="1e-5" />
      <origin xyz="0 0 0" rpy="0 0 0"/>
      <inertia ixx="1e-6" ixy="0" ixz="0" iyy="1e-6" iyz="0" izz="1e-6" />
    </inertial>
  </link>

  <joint name="hokuyo_joint" type="fixed">
    <axis xyz="0 0 0" />
    <origin xyz="0 0 0.65" rpy="0 0 0"/>
    <parent link="base_link"/>
    <child link="hokuyo_link"/>
  </joint>

 <!-- hokuyo -->
  <gazebo reference="hokuyo_link">
    <sensor type="gpu_ray" name="head_hokuyo_sensor">
      <pose>0 0 0 0 0 0</pose>
      <visualize>false</visualize>
      <update_rate>40</update_rate>
      <ray>
        <scan>
          <horizontal>
            <samples>720</samples>
            <resolution>1</resolution>
            <min_angle>-1.570796</min_angle>
            <max_angle>1.570796</max_angle>
          </horizontal>
        </scan>
        <range>
          <min>0.10</min>
          <max>30.0</max>
          <resolution>0.01</resolution>
        </range>
        <noise>
          <type>gaussian</type>
          <!-- Noise parameters based on published spec for Hokuyo laser
               achieving "+-30mm" accuracy at range < 10m.  A mean of 0.0m and
               stddev of 0.01m will put 99.7% of samples within 0.03m of the true
               reading. -->
          <mean>0.0</mean>
          <stddev>0.01</stddev>
        </noise>
      </ray>
      <plugin name="gazebo_ros_head_hokuyo_controller" filename="libgazebo_ros_gpu_laser.so">
        <topicName>/scan</topicName>
        <frameName>hokuyo_link</frameName>
      </plugin>
    </sensor>
  </gazebo>



  <gazebo reference="base_link">
    <material>
      Gazebo/White
    </material>
  </gazebo>

  <gazebo reference="extention">
    <material>
      Gazebo/White
    </material>
  </gazebo>

  <gazebo reference="fwheel_attach">
    <material>
      Gazebo/White
    </material>
  </gazebo>

  <gazebo reference="fwheel">
    <material>
      Gazebo/White
    </material>
    <mu1>0.001</mu1>
    <mu2>0.001</mu2>
  </gazebo>

  <gazebo reference="bwheel">
    <material>
      Gazebo/White
    </material>
    <mu1>0.001</mu1>
    <mu2>0.001</mu2>
  </gazebo>

  <gazebo reference="lwheel">
    <material>
      Gazebo/White
    </material>
    <mu1>100</mu1>
    <mu2>100</mu2>
  </gazebo>

  <gazebo reference="rwheel">
    <material>
      Gazebo/White
    </material>
    <mu1>100</mu1>
    <mu2>100</mu2>
  </gazebo> 



  


  

</robot>

